<mujoco model="morphology">
  <compiler angle="radian"/>
  <option>
    <flag contact="disable"/>
  </option>
  <default>
    <default class="/"/>
  </default>
  <asset>
    <mesh name="segment_0_vertebrae_vertebrae" class="/" file="vertebrae-1a6e59f61ff64431079c9651083134acb96bb971.stl" scale="0.001 0.001 0.001"/>
    <mesh name="segment_0_vertebrae_ball_bearing" class="/" file="ball_bearing-82cd80c511924a6cc447691ead255c788d7333b0.stl" scale="0.001 0.001 0.001"/>
    <mesh name="segment_0_vertebrae_connector" class="/" file="connector_vertebrae-2d8638b695ca1f84ac472fdfce7e747e1ca2dfe7.stl" scale="0.001 0.001 0.001"/>
    <mesh name="segment_0_plate_0_plate" class="/" file="ventral_dextral-060a11e3f2b5e60eee4297135455f714f4ea16c2.stl" scale="0.001 0.001 0.001"/>
    <mesh name="segment_0_plate_0_connector" class="/" file="connector_plate-d09c5eb60bcff5f07d3df710cbc22f9eca3981d3.stl" scale="0.001 0.001 0.001"/>
    <mesh name="segment_0_plate_1_plate" class="/" file="ventral_sinistral-05ad0dbf1065da702a69fe19888f3d61433fd0ce.stl" scale="0.001 0.001 0.001"/>
    <mesh name="segment_0_plate_1_connector" class="/" file="connector_plate-d09c5eb60bcff5f07d3df710cbc22f9eca3981d3.stl" scale="0.001 0.001 0.001"/>
    <mesh name="segment_0_plate_2_plate" class="/" file="dorsal_sinistral_even-ed8982753fa898a863a9e5d7ccb988f1e46f3228.stl" scale="0.001 0.001 0.001"/>
    <mesh name="segment_0_plate_2_connector" class="/" file="connector_plate-d09c5eb60bcff5f07d3df710cbc22f9eca3981d3.stl" scale="0.001 0.001 0.001"/>
    <mesh name="segment_0_plate_3_plate" class="/" file="dorsal_dextral_even-5969301c134747ca804c56f4081608dbc45343e3.stl" scale="0.001 0.001 0.001"/>
    <mesh name="segment_0_plate_3_connector" class="/" file="connector_plate-d09c5eb60bcff5f07d3df710cbc22f9eca3981d3.stl" scale="0.001 0.001 0.001"/>
  </asset>
  <worldbody>
    <body name="//unnamed_body_0">
      <body name="segment_0" pos="0 0 0" euler="0 0 0">
        <body name="segment_0_vertebrae" pos="0 0 0" euler="0 0 0">
          <geom name="segment_0_vertebrae_vertebrae" class="/" type="mesh" group="1" rgba="0.61960784313725492 0.14901960784313725 0.83137254901960789 1" mass="0.0045300000000000002" pos="0 0 0" mesh="segment_0_vertebrae_vertebrae"/>
          <geom name="segment_0_vertebrae_connector_ventral" class="/" type="mesh" group="1" rgba="0.34901960784313724 0.34901960784313724 0.34901960784313724 1" mass="6.9999999999999994e-05" pos="0.0178 0 0" euler="0 0 0" mesh="segment_0_vertebrae_connector"/>
          <geom name="segment_0_vertebrae_connector_dextral" class="/" type="mesh" group="1" rgba="0.34901960784313724 0.34901960784313724 0.34901960784313724 1" mass="6.9999999999999994e-05" pos="1.0899356512411443e-18 0.0178 0" euler="0 0 1.5707963267948966" mesh="segment_0_vertebrae_connector"/>
          <geom name="segment_0_vertebrae_connector_dorsal" class="/" type="mesh" group="1" rgba="0.34901960784313724 0.34901960784313724 0.34901960784313724 1" mass="6.9999999999999994e-05" pos="-0.0178 2.1798713024822886e-18 0" euler="0 0 3.1415926535897931" mesh="segment_0_vertebrae_connector"/>
          <geom name="segment_0_vertebrae_connector_sinistral" class="/" type="mesh" group="1" rgba="0.34901960784313724 0.34901960784313724 0.34901960784313724 1" mass="6.9999999999999994e-05" pos="-3.2698069537234327e-18 -0.0178 0" euler="0 0 4.7123889803846897" mesh="segment_0_vertebrae_connector"/>
          <site name="segment_0_vertebrae_s_tap_ventral" class="/" type="sphere" rgba="0.71764705882352942 0.33725490196078434 0.34901960784313724 1" size="0.001" pos="0.014999999999999999 0 0"/>
          <site name="segment_0_vertebrae_s_tap_sinistral" class="/" type="sphere" rgba="0.71764705882352942 0.33725490196078434 0.34901960784313724 1" size="0.001" pos="9.184850993605148e-19 0.014999999999999999 0"/>
          <site name="segment_0_vertebrae_s_tap_dorsal" class="/" type="sphere" rgba="0.71764705882352942 0.33725490196078434 0.34901960784313724 1" size="0.001" pos="-0.014999999999999999 1.8369701987210296e-18 0"/>
          <site name="segment_0_vertebrae_s_tap_dextral" class="/" type="sphere" rgba="0.71764705882352942 0.33725490196078434 0.34901960784313724 1" size="0.001" pos="-2.7554552980815444e-18 -0.014999999999999999 0"/>
          <body name="segment_0_plate_0" pos="0 0 0" euler="0 0 0">
            <geom name="segment_0_plate_0_plate" class="/" type="mesh" group="0" rgba="0.49019607843137253 0.70980392156862748 0.6588235294117647 1" mass="0.0091800000000000007" pos="0.036048303704890185 -0.036048303704890199 0.0074999999999999997" mesh="segment_0_plate_0_plate"/>
            <joint name="segment_0_plate_0_x_axis" class="/" type="slide" pos="0 0 0" axis="1 0 0" limited="true" stiffness="0" range="-0.0048999999999999998 0" damping="1"/>
            <joint name="segment_0_plate_0_y_axis" class="/" type="slide" pos="0 0 0" axis="0 1 0" limited="true" stiffness="0" range="0 0.0048999999999999998" damping="1"/>
            <site name="segment_0_plate_0_a_tap_end" class="/" type="sphere" rgba="0.71764705882352942 0.33725490196078434 0.34901960784313724 1" size="0.001" pos="0.036048303704890185 -0.036048303704890199 0.0074999999999999997"/>
            <site name="segment_0_plate_0_mvm_a_tap_proximal" class="/" type="sphere" rgba="0.71764705882352942 0.33725490196078434 0.34901960784313724 1" size="0.001" pos="0.043499999999999997 0 -0.0034999999999999996"/>
            <site name="segment_0_plate_0_mvm_a_tap_distal" class="/" type="sphere" rgba="0.71764705882352942 0.33725490196078434 0.34901960784313724 1" size="0.001" pos="0.043499999999999997 0 0.0034999999999999996"/>
            <site name="segment_0_plate_0_s_tap_x" class="/" type="sphere" rgba="0.71764705882352942 0.33725490196078434 0.34901960784313724 1" size="0.001" pos="0.051999999999999998 0 0"/>
            <site name="segment_0_plate_0_s_tap_y" class="/" type="sphere" rgba="0.71764705882352942 0.33725490196078434 0.34901960784313724 1" size="0.001" pos="0 -0.051999999999999998 0"/>
          </body>
          <body name="segment_0_plate_1" pos="0 0 0" euler="0 0 0">
            <geom name="segment_0_plate_1_plate" class="/" type="mesh" group="0" rgba="0.49019607843137253 0.70980392156862748 0.6588235294117647 1" mass="0.0090699999999999999" pos="0.036196796128939376 0.036196796128939356 0.0074999999999999997" mesh="segment_0_plate_1_plate"/>
            <geom name="segment_0_plate_1_connector_x" class="/" type="mesh" group="0" rgba="0.34901960784313724 0.34901960784313724 0.34901960784313724 1" mass="0.00013999999999999999" pos="0.037010000000000001 0 0" mesh="segment_0_plate_1_connector"/>
            <joint name="segment_0_plate_1_x_axis" class="/" type="slide" pos="0 0 0" axis="1 0 0" limited="true" stiffness="0" range="-0.0048999999999999998 0" damping="1"/>
            <joint name="segment_0_plate_1_y_axis" class="/" type="slide" pos="0 0 0" axis="0 1 0" limited="true" stiffness="0" range="-0.0048999999999999998 0" damping="1"/>
            <site name="segment_0_plate_1_a_tap_end" class="/" type="sphere" rgba="0.71764705882352942 0.33725490196078434 0.34901960784313724 1" size="0.001" pos="0.036196796128939376 0.036196796128939356 0.0074999999999999997"/>
            <site name="segment_0_plate_1_a_tap_ventral_sinistral_bottom" class="/" type="sphere" rgba="0.71764705882352942 0.33725490196078434 0.34901960784313724 1" size="0.001" pos="0.038386796128939374 0.0063867961289393559 -0.0074999999999999997"/>
            <site name="segment_0_plate_1_a_tap_ventral_sinistral_top" class="/" type="sphere" rgba="0.71764705882352942 0.33725490196078434 0.34901960784313724 1" size="0.001" pos="0.038386796128939374 0.0063867961289393559 0.0074999999999999997"/>
            <site name="segment_0_plate_1_a_tap_ventral_dextral_bottom" class="/" type="sphere" rgba="0.71764705882352942 0.33725490196078434 0.34901960784313724 1" size="0.001" pos="0.038398303704890183 -0.0056483037048901986 -0.0074999999999999997"/>
            <site name="segment_0_plate_1_a_tap_ventral_dextral_top" class="/" type="sphere" rgba="0.71764705882352942 0.33725490196078434 0.34901960784313724 1" size="0.001" pos="0.038398303704890183 -0.0056483037048901986 0.0074999999999999997"/>
            <site name="segment_0_plate_1_s_tap_x" class="/" type="sphere" rgba="0.71764705882352942 0.33725490196078434 0.34901960784313724 1" size="0.001" pos="0.048000000000000001 0 0"/>
            <site name="segment_0_plate_1_s_tap_y" class="/" type="sphere" rgba="0.71764705882352942 0.33725490196078434 0.34901960784313724 1" size="0.001" pos="0 0.051999999999999998 0"/>
            <site name="segment_0_plate_1_connector_x_s_tap" class="/" type="sphere" rgba="0.71764705882352942 0.33725490196078434 0.34901960784313724 1" size="0.001" pos="0.033309000000000005 0 0"/>
          </body>
          <body name="segment_0_plate_2" pos="0 0 0" euler="0 0 0">
            <geom name="segment_0_plate_2_plate" class="/" type="mesh" group="0" rgba="0.49019607843137253 0.70980392156862748 0.6588235294117647 1" mass="0.0094699999999999993" pos="-0.036203867196751234 0.036203867196751234 0.0074999999999999997" mesh="segment_0_plate_2_plate"/>
            <geom name="segment_0_plate_2_connector_x" class="/" type="mesh" group="0" rgba="0.34901960784313724 0.34901960784313724 0.34901960784313724 1" mass="0.00013999999999999999" pos="-0.037010000000000001 0 0" mesh="segment_0_plate_2_connector"/>
            <geom name="segment_0_plate_2_connector_y" class="/" type="mesh" group="0" rgba="0.34901960784313724 0.34901960784313724 0.34901960784313724 1" mass="0.00013999999999999999" pos="0 0.037010000000000001 0" euler="0 0 1.5707963267948966" mesh="segment_0_plate_2_connector"/>
            <joint name="segment_0_plate_2_x_axis" class="/" type="slide" pos="0 0 0" axis="1 0 0" limited="true" stiffness="0" range="0 0.0048999999999999998" damping="1"/>
            <joint name="segment_0_plate_2_y_axis" class="/" type="slide" pos="0 0 0" axis="0 1 0" limited="true" stiffness="0" range="-0.0048999999999999998 0" damping="1"/>
            <site name="segment_0_plate_2_a_tap_end" class="/" type="sphere" rgba="0.71764705882352942 0.33725490196078434 0.34901960784313724 1" size="0.001" pos="-0.036203867196751234 0.036203867196751234 0.0074999999999999997"/>
            <site name="segment_0_plate_2_a_tap_dorsal_sinistral_bottom" class="/" type="sphere" rgba="0.71764705882352942 0.33725490196078434 0.34901960784313724 1" size="0.001" pos="-0.038443867196751233 0.0063438671967512329 -0.0074999999999999997"/>
            <site name="segment_0_plate_2_a_tap_dorsal_sinistral_top" class="/" type="sphere" rgba="0.71764705882352942 0.33725490196078434 0.34901960784313724 1" size="0.001" pos="-0.038443867196751233 0.0063438671967512329 0.0074999999999999997"/>
            <site name="segment_0_plate_2_a_tap_dorsal_dextral_bottom" class="/" type="sphere" rgba="0.71764705882352942 0.33725490196078434 0.34901960784313724 1" size="0.001" pos="-0.038400643892047878 -0.0056606438920478695 -0.0074999999999999997"/>
            <site name="segment_0_plate_2_a_tap_dorsal_dextral_top" class="/" type="sphere" rgba="0.71764705882352942 0.33725490196078434 0.34901960784313724 1" size="0.001" pos="-0.038400643892047878 -0.0056606438920478695 0.0074999999999999997"/>
            <site name="segment_0_plate_2_s_tap_x" class="/" type="sphere" rgba="0.71764705882352942 0.33725490196078434 0.34901960784313724 1" size="0.001" pos="-0.048000000000000001 0 0"/>
            <site name="segment_0_plate_2_s_tap_y" class="/" type="sphere" rgba="0.71764705882352942 0.33725490196078434 0.34901960784313724 1" size="0.001" pos="0 0.048000000000000001 0"/>
            <site name="segment_0_plate_2_connector_x_s_tap" class="/" type="sphere" rgba="0.71764705882352942 0.33725490196078434 0.34901960784313724 1" size="0.001" pos="-0.033309000000000005 0 0"/>
            <site name="segment_0_plate_2_connector_y_s_tap" class="/" type="sphere" rgba="0.71764705882352942 0.33725490196078434 0.34901960784313724 1" size="0.001" pos="0 0.033309000000000005 0"/>
          </body>
          <body name="segment_0_plate_3" pos="0 0 0" euler="0 0 0">
            <geom name="segment_0_plate_3_plate" class="/" type="mesh" group="0" rgba="0.49019607843137253 0.70980392156862748 0.6588235294117647 1" mass="0.0090699999999999999" pos="-0.036380643892047877 -0.03638064389204787 0.0074999999999999997" mesh="segment_0_plate_3_plate"/>
            <geom name="segment_0_plate_3_connector_y" class="/" type="mesh" group="0" rgba="0.34901960784313724 0.34901960784313724 0.34901960784313724 1" mass="0.00013999999999999999" pos="0 -0.037010000000000001 0" euler="0 0 1.5707963267948966" mesh="segment_0_plate_3_connector"/>
            <joint name="segment_0_plate_3_x_axis" class="/" type="slide" pos="0 0 0" axis="1 0 0" limited="true" stiffness="0" range="0 0.0048999999999999998" damping="1"/>
            <joint name="segment_0_plate_3_y_axis" class="/" type="slide" pos="0 0 0" axis="0 1 0" limited="true" stiffness="0" range="0 0.0048999999999999998" damping="1"/>
            <site name="segment_0_plate_3_a_tap_end" class="/" type="sphere" rgba="0.71764705882352942 0.33725490196078434 0.34901960784313724 1" size="0.001" pos="-0.036380643892047877 -0.03638064389204787 0.0074999999999999997"/>
            <site name="segment_0_plate_3_s_tap_x" class="/" type="sphere" rgba="0.71764705882352942 0.33725490196078434 0.34901960784313724 1" size="0.001" pos="-0.051999999999999998 0 0"/>
            <site name="segment_0_plate_3_s_tap_y" class="/" type="sphere" rgba="0.71764705882352942 0.33725490196078434 0.34901960784313724 1" size="0.001" pos="0 -0.048000000000000001 0"/>
            <site name="segment_0_plate_3_connector_y_s_tap" class="/" type="sphere" rgba="0.71764705882352942 0.33725490196078434 0.34901960784313724 1" size="0.001" pos="0 -0.033309000000000005 0"/>
          </body>
        </body>
      </body>
    </body>
  </worldbody>
  <equality>
    <joint name="//unnamed_equality_0" class="/" joint1="segment_0_plate_0_x_axis" joint2="segment_0_plate_1_x_axis" polycoef="0 1 0 0 0"/>
    <joint name="//unnamed_equality_1" class="/" joint1="segment_0_plate_0_y_axis" joint2="segment_0_plate_1_y_axis" polycoef="0 -1 0 0 0"/>
    <joint name="//unnamed_equality_2" class="/" joint1="segment_0_plate_2_x_axis" joint2="segment_0_plate_3_x_axis" polycoef="0 1 0 0 0"/>
    <joint name="//unnamed_equality_3" class="/" joint1="segment_0_plate_2_y_axis" joint2="segment_0_plate_3_y_axis" polycoef="0 -1 0 0 0"/>
    <joint name="//unnamed_equality_4" class="/" joint1="segment_0_plate_0_x_axis" joint2="segment_0_plate_3_x_axis" polycoef="0 -1 0 0 0"/>
    <joint name="//unnamed_equality_5" class="/" joint1="segment_0_plate_0_y_axis" joint2="segment_0_plate_3_y_axis" polycoef="0 1 0 0 0"/>
    <joint name="//unnamed_equality_6" class="/" joint1="segment_0_plate_1_x_axis" joint2="segment_0_plate_2_x_axis" polycoef="0 -1 0 0 0"/>
    <joint name="//unnamed_equality_7" class="/" joint1="segment_0_plate_1_y_axis" joint2="segment_0_plate_2_y_axis" polycoef="0 1 0 0 0"/>
  </equality>
  <tendon>
    <spatial name="segment_0_vertebral_spine_ventral" class="/" width="0.00050000000000000001" rgba="0.34901960784313724 0.34901960784313724 0.34901960784313724 1" stiffness="0" damping="1">
      <site site="segment_0_vertebrae_s_tap_ventral"/>
      <site site="segment_0_plate_1_connector_x_s_tap"/>
      <site site="segment_0_plate_1_s_tap_x"/>
      <site site="segment_0_plate_0_s_tap_x"/>
    </spatial>
    <spatial name="segment_0_vertebral_spine_sinistral" class="/" width="0.00050000000000000001" rgba="0.34901960784313724 0.34901960784313724 0.34901960784313724 1" stiffness="0" damping="1">
      <site site="segment_0_vertebrae_s_tap_sinistral"/>
      <site site="segment_0_plate_2_connector_y_s_tap"/>
      <site site="segment_0_plate_2_s_tap_y"/>
      <site site="segment_0_plate_1_s_tap_y"/>
    </spatial>
    <spatial name="segment_0_vertebral_spine_dorsal" class="/" width="0.00050000000000000001" rgba="0.34901960784313724 0.34901960784313724 0.34901960784313724 1" stiffness="0" damping="1">
      <site site="segment_0_vertebrae_s_tap_dorsal"/>
      <site site="segment_0_plate_2_connector_x_s_tap"/>
      <site site="segment_0_plate_2_s_tap_x"/>
      <site site="segment_0_plate_3_s_tap_x"/>
    </spatial>
    <spatial name="segment_0_vertebral_spine_dextral" class="/" width="0.00050000000000000001" rgba="0.34901960784313724 0.34901960784313724 0.34901960784313724 1" stiffness="0" damping="1">
      <site site="segment_0_vertebrae_s_tap_dextral"/>
      <site site="segment_0_plate_3_connector_y_s_tap"/>
      <site site="segment_0_plate_3_s_tap_y"/>
      <site site="segment_0_plate_0_s_tap_y"/>
    </spatial>
  </tendon>
</mujoco>
