<mujoco model="floor">
  <compiler boundmass="1.0000000000000001e-05" boundinertia="9.9999999999999994e-12" coordinate="local" angle="radian" eulerseq="xyz"/>
  <option timestep="0.002" cone="elliptic" noslip_iterations="5" noslip_tolerance="0"/>
  <visual>
    <headlight ambient="0.40000000000000002 0.40000000000000002 0.40000000000000002" diffuse="0.80000000000000004 0.80000000000000004 0.80000000000000004" specular="0.10000000000000001 0.10000000000000001 0.10000000000000001"/>
    <map znear="0.01"/>
    <scale forcewidth="0.01" contactwidth="0.059999999999999998" contactheight="0.01" jointwidth="0.01" framelength="0.29999999999999999" framewidth="0.01"/>
  </visual>
  <default>
    <default class="/"/>
    <default class="target/"/>
    <default class="morphology/"/>
  </default>
  <asset>
    <texture name="groundplane" type="2d" builtin="checker" rgb1="0.20000000000000001 0.29999999999999999 0.40000000000000002" rgb2="0.10000000000000001 0.20000000000000001 0.29999999999999999" mark="edge" markrgb="0.80000000000000004 0.80000000000000004 0.80000000000000004" width="200" height="200"/>
    <material name="groundplane" class="/" texture="groundplane" texrepeat="2 2" texuniform="true" reflectance="0.20000000000000001"/>
  </asset>
  <worldbody>
    <geom name="groundplane" class="/" type="plane" size="8 8 0.25" material="groundplane"/>
    <camera name="top_camera" class="/" fovy="10.058147163570894" pos="0 0 100" quat="1 0 0 0"/>
    <body name="target/">
      <geom name="target/target_site" class="target/" type="sphere" rgba="0.71764705882352942 0.33725490196078434 0.34901960784313724 1" size="0.20000000000000001" contype="0" conaffinity="0"/>
      <joint name="target_x" axis="1 0 0" type="slide"/>
      <joint name="target_y" axis="0 1 0" type="slide"/>
    </body>
    <body name="morphology/">
      <freejoint name="morphology/"/>
      <body name="morphology//unnamed_body_0">
        <body name="morphology/torso" pos="0 0 0" euler="0 0 0">
          <geom name="morphology//unnamed_geom_0" class="morphology/" type="sphere" size="0.10000000000000001" rgba="0.49019607843137253 0.70980392156862748 0.6588235294117647 1"/>
          <body name="morphology/arm_0" pos="0.10000000000000001 0 0" euler="0 0 0">
            <body name="morphology/arm_0_segment_0" pos="0 0 0" euler="0 0 0">
              <geom name="morphology/arm_0_segment_0_capsule" class="morphology/" type="capsule" size="0.025000000000000001 0.050000000000000003" rgba="0.49019607843137253 0.70980392156862748 0.6588235294117647 1" pos="0.075000000000000011 0 0" euler="0 1.5707963267948966 0"/>
              <joint name="morphology/arm_0_segment_0_in_plane_joint" class="morphology/" type="hinge" axis="0 0 1" limited="true" stiffness="0.10000000000000001" range="-0.3490658503988659 0.3490658503988659" damping="0.10000000000000001"/>
              <joint name="morphology/arm_0_segment_0_out_of_plane_joint" class="morphology/" type="hinge" axis="0 1 0" limited="true" stiffness="0.10000000000000001" range="-0.3490658503988659 0.3490658503988659" damping="0.10000000000000001"/>
              <body name="morphology/arm_0_segment_1" pos="0.15000000000000002 0 0" euler="0 0 0">
                <geom name="morphology/arm_0_segment_1_capsule" class="morphology/" type="capsule" size="0.025000000000000001 0.050000000000000003" rgba="0.49019607843137253 0.70980392156862748 0.6588235294117647 1" pos="0.075000000000000011 0 0" euler="0 1.5707963267948966 0"/>
                <joint name="morphology/arm_0_segment_1_in_plane_joint" class="morphology/" type="hinge" axis="0 0 1" limited="true" stiffness="0.10000000000000001" range="-0.3490658503988659 0.3490658503988659" damping="0.10000000000000001"/>
                <joint name="morphology/arm_0_segment_1_out_of_plane_joint" class="morphology/" type="hinge" axis="0 1 0" limited="true" stiffness="0.10000000000000001" range="-0.3490658503988659 0.3490658503988659" damping="0.10000000000000001"/>
                <body name="morphology/arm_0_segment_2" pos="0.15000000000000002 0 0" euler="0 0 0">
                  <geom name="morphology/arm_0_segment_2_capsule" class="morphology/" type="capsule" size="0.025000000000000001 0.050000000000000003" rgba="0.49019607843137253 0.70980392156862748 0.6588235294117647 1" pos="0.075000000000000011 0 0" euler="0 1.5707963267948966 0"/>
                  <joint name="morphology/arm_0_segment_2_in_plane_joint" class="morphology/" type="hinge" axis="0 0 1" limited="true" stiffness="0.10000000000000001" range="-0.3490658503988659 0.3490658503988659" damping="0.10000000000000001"/>
                  <joint name="morphology/arm_0_segment_2_out_of_plane_joint" class="morphology/" type="hinge" axis="0 1 0" limited="true" stiffness="0.10000000000000001" range="-0.3490658503988659 0.3490658503988659" damping="0.10000000000000001"/>
                </body>
              </body>
            </body>
          </body>
          <body name="morphology/arm_1" pos="6.1232339957367663e-18 0.10000000000000001 0" euler="0 0 1.5707963267948966">
            <body name="morphology/arm_1_segment_0" pos="0 0 0" euler="0 0 0">
              <geom name="morphology/arm_1_segment_0_capsule" class="morphology/" type="capsule" size="0.025000000000000001 0.050000000000000003" rgba="0.49019607843137253 0.70980392156862748 0.6588235294117647 1" pos="0.075000000000000011 0 0" euler="0 1.5707963267948966 0"/>
              <joint name="morphology/arm_1_segment_0_in_plane_joint" class="morphology/" type="hinge" axis="0 0 1" limited="true" stiffness="0.10000000000000001" range="-0.3490658503988659 0.3490658503988659" damping="0.10000000000000001"/>
              <joint name="morphology/arm_1_segment_0_out_of_plane_joint" class="morphology/" type="hinge" axis="0 1 0" limited="true" stiffness="0.10000000000000001" range="-0.3490658503988659 0.3490658503988659" damping="0.10000000000000001"/>
              <body name="morphology/arm_1_segment_1" pos="0.15000000000000002 0 0" euler="0 0 0">
                <geom name="morphology/arm_1_segment_1_capsule" class="morphology/" type="capsule" size="0.025000000000000001 0.050000000000000003" rgba="0.49019607843137253 0.70980392156862748 0.6588235294117647 1" pos="0.075000000000000011 0 0" euler="0 1.5707963267948966 0"/>
                <joint name="morphology/arm_1_segment_1_in_plane_joint" class="morphology/" type="hinge" axis="0 0 1" limited="true" stiffness="0.10000000000000001" range="-0.3490658503988659 0.3490658503988659" damping="0.10000000000000001"/>
                <joint name="morphology/arm_1_segment_1_out_of_plane_joint" class="morphology/" type="hinge" axis="0 1 0" limited="true" stiffness="0.10000000000000001" range="-0.3490658503988659 0.3490658503988659" damping="0.10000000000000001"/>
                <body name="morphology/arm_1_segment_2" pos="0.15000000000000002 0 0" euler="0 0 0">
                  <geom name="morphology/arm_1_segment_2_capsule" class="morphology/" type="capsule" size="0.025000000000000001 0.050000000000000003" rgba="0.49019607843137253 0.70980392156862748 0.6588235294117647 1" pos="0.075000000000000011 0 0" euler="0 1.5707963267948966 0"/>
                  <joint name="morphology/arm_1_segment_2_in_plane_joint" class="morphology/" type="hinge" axis="0 0 1" limited="true" stiffness="0.10000000000000001" range="-0.3490658503988659 0.3490658503988659" damping="0.10000000000000001"/>
                  <joint name="morphology/arm_1_segment_2_out_of_plane_joint" class="morphology/" type="hinge" axis="0 1 0" limited="true" stiffness="0.10000000000000001" range="-0.3490658503988659 0.3490658503988659" damping="0.10000000000000001"/>
                </body>
              </body>
            </body>
          </body>
          <body name="morphology/arm_2" pos="-0.10000000000000001 1.2246467991473533e-17 0" euler="0 0 3.1415926535897931">
            <body name="morphology/arm_2_segment_0" pos="0 0 0" euler="0 0 0">
              <geom name="morphology/arm_2_segment_0_capsule" class="morphology/" type="capsule" size="0.025000000000000001 0.050000000000000003" rgba="0.49019607843137253 0.70980392156862748 0.6588235294117647 1" pos="0.075000000000000011 0 0" euler="0 1.5707963267948966 0"/>
              <joint name="morphology/arm_2_segment_0_in_plane_joint" class="morphology/" type="hinge" axis="0 0 1" limited="true" stiffness="0.10000000000000001" range="-0.3490658503988659 0.3490658503988659" damping="0.10000000000000001"/>
              <joint name="morphology/arm_2_segment_0_out_of_plane_joint" class="morphology/" type="hinge" axis="0 1 0" limited="true" stiffness="0.10000000000000001" range="-0.3490658503988659 0.3490658503988659" damping="0.10000000000000001"/>
              <body name="morphology/arm_2_segment_1" pos="0.15000000000000002 0 0" euler="0 0 0">
                <geom name="morphology/arm_2_segment_1_capsule" class="morphology/" type="capsule" size="0.025000000000000001 0.050000000000000003" rgba="0.49019607843137253 0.70980392156862748 0.6588235294117647 1" pos="0.075000000000000011 0 0" euler="0 1.5707963267948966 0"/>
                <joint name="morphology/arm_2_segment_1_in_plane_joint" class="morphology/" type="hinge" axis="0 0 1" limited="true" stiffness="0.10000000000000001" range="-0.3490658503988659 0.3490658503988659" damping="0.10000000000000001"/>
                <joint name="morphology/arm_2_segment_1_out_of_plane_joint" class="morphology/" type="hinge" axis="0 1 0" limited="true" stiffness="0.10000000000000001" range="-0.3490658503988659 0.3490658503988659" damping="0.10000000000000001"/>
                <body name="morphology/arm_2_segment_2" pos="0.15000000000000002 0 0" euler="0 0 0">
                  <geom name="morphology/arm_2_segment_2_capsule" class="morphology/" type="capsule" size="0.025000000000000001 0.050000000000000003" rgba="0.49019607843137253 0.70980392156862748 0.6588235294117647 1" pos="0.075000000000000011 0 0" euler="0 1.5707963267948966 0"/>
                  <joint name="morphology/arm_2_segment_2_in_plane_joint" class="morphology/" type="hinge" axis="0 0 1" limited="true" stiffness="0.10000000000000001" range="-0.3490658503988659 0.3490658503988659" damping="0.10000000000000001"/>
                  <joint name="morphology/arm_2_segment_2_out_of_plane_joint" class="morphology/" type="hinge" axis="0 1 0" limited="true" stiffness="0.10000000000000001" range="-0.3490658503988659 0.3490658503988659" damping="0.10000000000000001"/>
                </body>
              </body>
            </body>
          </body>
          <body name="morphology/arm_3" pos="-1.8369701987210297e-17 -0.10000000000000001 0" euler="0 0 4.7123889803846897">
            <body name="morphology/arm_3_segment_0" pos="0 0 0" euler="0 0 0">
              <geom name="morphology/arm_3_segment_0_capsule" class="morphology/" type="capsule" size="0.025000000000000001 0.050000000000000003" rgba="0.49019607843137253 0.70980392156862748 0.6588235294117647 1" pos="0.075000000000000011 0 0" euler="0 1.5707963267948966 0"/>
              <joint name="morphology/arm_3_segment_0_in_plane_joint" class="morphology/" type="hinge" axis="0 0 1" limited="true" stiffness="0.10000000000000001" range="-0.3490658503988659 0.3490658503988659" damping="0.10000000000000001"/>
              <joint name="morphology/arm_3_segment_0_out_of_plane_joint" class="morphology/" type="hinge" axis="0 1 0" limited="true" stiffness="0.10000000000000001" range="-0.3490658503988659 0.3490658503988659" damping="0.10000000000000001"/>
              <body name="morphology/arm_3_segment_1" pos="0.15000000000000002 0 0" euler="0 0 0">
                <geom name="morphology/arm_3_segment_1_capsule" class="morphology/" type="capsule" size="0.025000000000000001 0.050000000000000003" rgba="0.49019607843137253 0.70980392156862748 0.6588235294117647 1" pos="0.075000000000000011 0 0" euler="0 1.5707963267948966 0"/>
                <joint name="morphology/arm_3_segment_1_in_plane_joint" class="morphology/" type="hinge" axis="0 0 1" limited="true" stiffness="0.10000000000000001" range="-0.3490658503988659 0.3490658503988659" damping="0.10000000000000001"/>
                <joint name="morphology/arm_3_segment_1_out_of_plane_joint" class="morphology/" type="hinge" axis="0 1 0" limited="true" stiffness="0.10000000000000001" range="-0.3490658503988659 0.3490658503988659" damping="0.10000000000000001"/>
                <body name="morphology/arm_3_segment_2" pos="0.15000000000000002 0 0" euler="0 0 0">
                  <geom name="morphology/arm_3_segment_2_capsule" class="morphology/" type="capsule" size="0.025000000000000001 0.050000000000000003" rgba="0.49019607843137253 0.70980392156862748 0.6588235294117647 1" pos="0.075000000000000011 0 0" euler="0 1.5707963267948966 0"/>
                  <joint name="morphology/arm_3_segment_2_in_plane_joint" class="morphology/" type="hinge" axis="0 0 1" limited="true" stiffness="0.10000000000000001" range="-0.3490658503988659 0.3490658503988659" damping="0.10000000000000001"/>
                  <joint name="morphology/arm_3_segment_2_out_of_plane_joint" class="morphology/" type="hinge" axis="0 1 0" limited="true" stiffness="0.10000000000000001" range="-0.3490658503988659 0.3490658503988659" damping="0.10000000000000001"/>
                </body>
              </body>
            </body>
          </body>
          <camera name="morphology/side_camera" class="morphology/" mode="track" pos="0 -5 6" quat="0.93969262078590843 0.34202014332566871 0 0"/>
        </body>
      </body>
    </body>
  </worldbody>
  <actuator>
    <position name="morphology/arm_0_segment_0_in_plane_joint_p_control" class="morphology/" ctrllimited="true" ctrlrange="-0.3490658503988659 0.3490658503988659" joint="morphology/arm_0_segment_0_in_plane_joint" kp="10"/>
    <position name="morphology/arm_0_segment_0_out_of_plane_joint_p_control" class="morphology/" ctrllimited="true" ctrlrange="-0.3490658503988659 0.3490658503988659" joint="morphology/arm_0_segment_0_out_of_plane_joint" kp="10"/>
    <position name="morphology/arm_0_segment_1_in_plane_joint_p_control" class="morphology/" ctrllimited="true" ctrlrange="-0.3490658503988659 0.3490658503988659" joint="morphology/arm_0_segment_1_in_plane_joint" kp="10"/>
    <position name="morphology/arm_0_segment_1_out_of_plane_joint_p_control" class="morphology/" ctrllimited="true" ctrlrange="-0.3490658503988659 0.3490658503988659" joint="morphology/arm_0_segment_1_out_of_plane_joint" kp="10"/>
    <position name="morphology/arm_0_segment_2_in_plane_joint_p_control" class="morphology/" ctrllimited="true" ctrlrange="-0.3490658503988659 0.3490658503988659" joint="morphology/arm_0_segment_2_in_plane_joint" kp="10"/>
    <position name="morphology/arm_0_segment_2_out_of_plane_joint_p_control" class="morphology/" ctrllimited="true" ctrlrange="-0.3490658503988659 0.3490658503988659" joint="morphology/arm_0_segment_2_out_of_plane_joint" kp="10"/>
    <position name="morphology/arm_1_segment_0_in_plane_joint_p_control" class="morphology/" ctrllimited="true" ctrlrange="-0.3490658503988659 0.3490658503988659" joint="morphology/arm_1_segment_0_in_plane_joint" kp="10"/>
    <position name="morphology/arm_1_segment_0_out_of_plane_joint_p_control" class="morphology/" ctrllimited="true" ctrlrange="-0.3490658503988659 0.3490658503988659" joint="morphology/arm_1_segment_0_out_of_plane_joint" kp="10"/>
    <position name="morphology/arm_1_segment_1_in_plane_joint_p_control" class="morphology/" ctrllimited="true" ctrlrange="-0.3490658503988659 0.3490658503988659" joint="morphology/arm_1_segment_1_in_plane_joint" kp="10"/>
    <position name="morphology/arm_1_segment_1_out_of_plane_joint_p_control" class="morphology/" ctrllimited="true" ctrlrange="-0.3490658503988659 0.3490658503988659" joint="morphology/arm_1_segment_1_out_of_plane_joint" kp="10"/>
    <position name="morphology/arm_1_segment_2_in_plane_joint_p_control" class="morphology/" ctrllimited="true" ctrlrange="-0.3490658503988659 0.3490658503988659" joint="morphology/arm_1_segment_2_in_plane_joint" kp="10"/>
    <position name="morphology/arm_1_segment_2_out_of_plane_joint_p_control" class="morphology/" ctrllimited="true" ctrlrange="-0.3490658503988659 0.3490658503988659" joint="morphology/arm_1_segment_2_out_of_plane_joint" kp="10"/>
    <position name="morphology/arm_2_segment_0_in_plane_joint_p_control" class="morphology/" ctrllimited="true" ctrlrange="-0.3490658503988659 0.3490658503988659" joint="morphology/arm_2_segment_0_in_plane_joint" kp="10"/>
    <position name="morphology/arm_2_segment_0_out_of_plane_joint_p_control" class="morphology/" ctrllimited="true" ctrlrange="-0.3490658503988659 0.3490658503988659" joint="morphology/arm_2_segment_0_out_of_plane_joint" kp="10"/>
    <position name="morphology/arm_2_segment_1_in_plane_joint_p_control" class="morphology/" ctrllimited="true" ctrlrange="-0.3490658503988659 0.3490658503988659" joint="morphology/arm_2_segment_1_in_plane_joint" kp="10"/>
    <position name="morphology/arm_2_segment_1_out_of_plane_joint_p_control" class="morphology/" ctrllimited="true" ctrlrange="-0.3490658503988659 0.3490658503988659" joint="morphology/arm_2_segment_1_out_of_plane_joint" kp="10"/>
    <position name="morphology/arm_2_segment_2_in_plane_joint_p_control" class="morphology/" ctrllimited="true" ctrlrange="-0.3490658503988659 0.3490658503988659" joint="morphology/arm_2_segment_2_in_plane_joint" kp="10"/>
    <position name="morphology/arm_2_segment_2_out_of_plane_joint_p_control" class="morphology/" ctrllimited="true" ctrlrange="-0.3490658503988659 0.3490658503988659" joint="morphology/arm_2_segment_2_out_of_plane_joint" kp="10"/>
    <position name="morphology/arm_3_segment_0_in_plane_joint_p_control" class="morphology/" ctrllimited="true" ctrlrange="-0.3490658503988659 0.3490658503988659" joint="morphology/arm_3_segment_0_in_plane_joint" kp="10"/>
    <position name="morphology/arm_3_segment_0_out_of_plane_joint_p_control" class="morphology/" ctrllimited="true" ctrlrange="-0.3490658503988659 0.3490658503988659" joint="morphology/arm_3_segment_0_out_of_plane_joint" kp="10"/>
    <position name="morphology/arm_3_segment_1_in_plane_joint_p_control" class="morphology/" ctrllimited="true" ctrlrange="-0.3490658503988659 0.3490658503988659" joint="morphology/arm_3_segment_1_in_plane_joint" kp="10"/>
    <position name="morphology/arm_3_segment_1_out_of_plane_joint_p_control" class="morphology/" ctrllimited="true" ctrlrange="-0.3490658503988659 0.3490658503988659" joint="morphology/arm_3_segment_1_out_of_plane_joint" kp="10"/>
    <position name="morphology/arm_3_segment_2_in_plane_joint_p_control" class="morphology/" ctrllimited="true" ctrlrange="-0.3490658503988659 0.3490658503988659" joint="morphology/arm_3_segment_2_in_plane_joint" kp="10"/>
    <position name="morphology/arm_3_segment_2_out_of_plane_joint_p_control" class="morphology/" ctrllimited="true" ctrlrange="-0.3490658503988659 0.3490658503988659" joint="morphology/arm_3_segment_2_out_of_plane_joint" kp="10"/>
  </actuator>
  <sensor>
    <framelinvel name="morphology/torso_framelinvel" objtype="body" objname="morphology/torso"/>
    <frameangvel name="morphology/torso_frameangvel" objtype="body" objname="morphology/torso"/>
    <jointpos name="morphology/arm_0_segment_0_in_plane_joint_jointpos_sensor" joint="morphology/arm_0_segment_0_in_plane_joint"/>
    <jointvel name="morphology/arm_0_segment_0_in_plane_joint_jointvel_sensor" joint="morphology/arm_0_segment_0_in_plane_joint"/>
    <jointpos name="morphology/arm_0_segment_0_out_of_plane_joint_jointpos_sensor" joint="morphology/arm_0_segment_0_out_of_plane_joint"/>
    <jointvel name="morphology/arm_0_segment_0_out_of_plane_joint_jointvel_sensor" joint="morphology/arm_0_segment_0_out_of_plane_joint"/>
    <jointpos name="morphology/arm_0_segment_1_in_plane_joint_jointpos_sensor" joint="morphology/arm_0_segment_1_in_plane_joint"/>
    <jointvel name="morphology/arm_0_segment_1_in_plane_joint_jointvel_sensor" joint="morphology/arm_0_segment_1_in_plane_joint"/>
    <jointpos name="morphology/arm_0_segment_1_out_of_plane_joint_jointpos_sensor" joint="morphology/arm_0_segment_1_out_of_plane_joint"/>
    <jointvel name="morphology/arm_0_segment_1_out_of_plane_joint_jointvel_sensor" joint="morphology/arm_0_segment_1_out_of_plane_joint"/>
    <jointpos name="morphology/arm_0_segment_2_in_plane_joint_jointpos_sensor" joint="morphology/arm_0_segment_2_in_plane_joint"/>
    <jointvel name="morphology/arm_0_segment_2_in_plane_joint_jointvel_sensor" joint="morphology/arm_0_segment_2_in_plane_joint"/>
    <jointpos name="morphology/arm_0_segment_2_out_of_plane_joint_jointpos_sensor" joint="morphology/arm_0_segment_2_out_of_plane_joint"/>
    <jointvel name="morphology/arm_0_segment_2_out_of_plane_joint_jointvel_sensor" joint="morphology/arm_0_segment_2_out_of_plane_joint"/>
    <jointpos name="morphology/arm_1_segment_0_in_plane_joint_jointpos_sensor" joint="morphology/arm_1_segment_0_in_plane_joint"/>
    <jointvel name="morphology/arm_1_segment_0_in_plane_joint_jointvel_sensor" joint="morphology/arm_1_segment_0_in_plane_joint"/>
    <jointpos name="morphology/arm_1_segment_0_out_of_plane_joint_jointpos_sensor" joint="morphology/arm_1_segment_0_out_of_plane_joint"/>
    <jointvel name="morphology/arm_1_segment_0_out_of_plane_joint_jointvel_sensor" joint="morphology/arm_1_segment_0_out_of_plane_joint"/>
    <jointpos name="morphology/arm_1_segment_1_in_plane_joint_jointpos_sensor" joint="morphology/arm_1_segment_1_in_plane_joint"/>
    <jointvel name="morphology/arm_1_segment_1_in_plane_joint_jointvel_sensor" joint="morphology/arm_1_segment_1_in_plane_joint"/>
    <jointpos name="morphology/arm_1_segment_1_out_of_plane_joint_jointpos_sensor" joint="morphology/arm_1_segment_1_out_of_plane_joint"/>
    <jointvel name="morphology/arm_1_segment_1_out_of_plane_joint_jointvel_sensor" joint="morphology/arm_1_segment_1_out_of_plane_joint"/>
    <jointpos name="morphology/arm_1_segment_2_in_plane_joint_jointpos_sensor" joint="morphology/arm_1_segment_2_in_plane_joint"/>
    <jointvel name="morphology/arm_1_segment_2_in_plane_joint_jointvel_sensor" joint="morphology/arm_1_segment_2_in_plane_joint"/>
    <jointpos name="morphology/arm_1_segment_2_out_of_plane_joint_jointpos_sensor" joint="morphology/arm_1_segment_2_out_of_plane_joint"/>
    <jointvel name="morphology/arm_1_segment_2_out_of_plane_joint_jointvel_sensor" joint="morphology/arm_1_segment_2_out_of_plane_joint"/>
    <jointpos name="morphology/arm_2_segment_0_in_plane_joint_jointpos_sensor" joint="morphology/arm_2_segment_0_in_plane_joint"/>
    <jointvel name="morphology/arm_2_segment_0_in_plane_joint_jointvel_sensor" joint="morphology/arm_2_segment_0_in_plane_joint"/>
    <jointpos name="morphology/arm_2_segment_0_out_of_plane_joint_jointpos_sensor" joint="morphology/arm_2_segment_0_out_of_plane_joint"/>
    <jointvel name="morphology/arm_2_segment_0_out_of_plane_joint_jointvel_sensor" joint="morphology/arm_2_segment_0_out_of_plane_joint"/>
    <jointpos name="morphology/arm_2_segment_1_in_plane_joint_jointpos_sensor" joint="morphology/arm_2_segment_1_in_plane_joint"/>
    <jointvel name="morphology/arm_2_segment_1_in_plane_joint_jointvel_sensor" joint="morphology/arm_2_segment_1_in_plane_joint"/>
    <jointpos name="morphology/arm_2_segment_1_out_of_plane_joint_jointpos_sensor" joint="morphology/arm_2_segment_1_out_of_plane_joint"/>
    <jointvel name="morphology/arm_2_segment_1_out_of_plane_joint_jointvel_sensor" joint="morphology/arm_2_segment_1_out_of_plane_joint"/>
    <jointpos name="morphology/arm_2_segment_2_in_plane_joint_jointpos_sensor" joint="morphology/arm_2_segment_2_in_plane_joint"/>
    <jointvel name="morphology/arm_2_segment_2_in_plane_joint_jointvel_sensor" joint="morphology/arm_2_segment_2_in_plane_joint"/>
    <jointpos name="morphology/arm_2_segment_2_out_of_plane_joint_jointpos_sensor" joint="morphology/arm_2_segment_2_out_of_plane_joint"/>
    <jointvel name="morphology/arm_2_segment_2_out_of_plane_joint_jointvel_sensor" joint="morphology/arm_2_segment_2_out_of_plane_joint"/>
    <jointpos name="morphology/arm_3_segment_0_in_plane_joint_jointpos_sensor" joint="morphology/arm_3_segment_0_in_plane_joint"/>
    <jointvel name="morphology/arm_3_segment_0_in_plane_joint_jointvel_sensor" joint="morphology/arm_3_segment_0_in_plane_joint"/>
    <jointpos name="morphology/arm_3_segment_0_out_of_plane_joint_jointpos_sensor" joint="morphology/arm_3_segment_0_out_of_plane_joint"/>
    <jointvel name="morphology/arm_3_segment_0_out_of_plane_joint_jointvel_sensor" joint="morphology/arm_3_segment_0_out_of_plane_joint"/>
    <jointpos name="morphology/arm_3_segment_1_in_plane_joint_jointpos_sensor" joint="morphology/arm_3_segment_1_in_plane_joint"/>
    <jointvel name="morphology/arm_3_segment_1_in_plane_joint_jointvel_sensor" joint="morphology/arm_3_segment_1_in_plane_joint"/>
    <jointpos name="morphology/arm_3_segment_1_out_of_plane_joint_jointpos_sensor" joint="morphology/arm_3_segment_1_out_of_plane_joint"/>
    <jointvel name="morphology/arm_3_segment_1_out_of_plane_joint_jointvel_sensor" joint="morphology/arm_3_segment_1_out_of_plane_joint"/>
    <jointpos name="morphology/arm_3_segment_2_in_plane_joint_jointpos_sensor" joint="morphology/arm_3_segment_2_in_plane_joint"/>
    <jointvel name="morphology/arm_3_segment_2_in_plane_joint_jointvel_sensor" joint="morphology/arm_3_segment_2_in_plane_joint"/>
    <jointpos name="morphology/arm_3_segment_2_out_of_plane_joint_jointpos_sensor" joint="morphology/arm_3_segment_2_out_of_plane_joint"/>
    <jointvel name="morphology/arm_3_segment_2_out_of_plane_joint_jointvel_sensor" joint="morphology/arm_3_segment_2_out_of_plane_joint"/>
  </sensor>
</mujoco>
